import { async } from 'regenerator-runtime';
import { TIMEOUT_SEC } from './config.js';

const timeout = function (s) {
  return new Promise(function (_, reject) {
    setTimeout(function () {
      reject(new Error(`Request took too long! Timeout after ${s} second`));
    }, s * 1000);
  });
};

export const getJSON = async function (url) {
  try {
    const res = await Promise.race([fetch(url), timeout(TIMEOUT_SEC)]);
    const data = await res.json();

    if (!res.ok) throw new Error(`${data.message} (${res.status})`);

    return data;
  } catch (err) {
    // Original error occured here
    // Re-throwing error, because we want to handle the error in 'model.js', not here
    // If not, in case of error, the promise that returns from here will still be returned as fulfilled (successful) promise
    throw err;
  }
};
